2019-10-07 11:35:32,578 ERROR: Exception on /login [POST] [in /home/senay/Documents/blog/venv/lib/python3.5/site-packages/flask/app.py:1891]
Traceback (most recent call last):
  File "/home/senay/Documents/blog/venv/lib/python3.5/site-packages/flask/app.py", line 2446, in wsgi_app
    response = self.full_dispatch_request()
  File "/home/senay/Documents/blog/venv/lib/python3.5/site-packages/flask/app.py", line 1951, in full_dispatch_request
    rv = self.handle_user_exception(e)
  File "/home/senay/Documents/blog/venv/lib/python3.5/site-packages/flask/app.py", line 1820, in handle_user_exception
    reraise(exc_type, exc_value, tb)
  File "/home/senay/Documents/blog/venv/lib/python3.5/site-packages/flask/_compat.py", line 39, in reraise
    raise value
  File "/home/senay/Documents/blog/venv/lib/python3.5/site-packages/flask/app.py", line 1949, in full_dispatch_request
    rv = self.dispatch_request()
  File "/home/senay/Documents/blog/venv/lib/python3.5/site-packages/flask/app.py", line 1935, in dispatch_request
    return self.view_functions[rule.endpoint](**req.view_args)
  File "/home/senay/Documents/blog/app/routes.py", line 48, in login
    if not next_page or url_parse(next_page).netloc != '':
NameError: name 'url_parse' is not defined
2019-10-07 12:04:58,253 INFO: Microblog startup [in /home/senay/Documents/blog/app/__init__.py:46]
2019-10-07 12:05:33,178 INFO: Microblog startup [in /home/senay/Documents/blog/app/__init__.py:46]
2019-10-07 15:43:53,370 INFO: Microblog startup [in /home/senay/Documents/blog/app/__init__.py:46]
2019-10-07 16:18:34,532 INFO: Microblog startup [in /home/senay/Documents/blog/app/__init__.py:46]
2019-10-07 16:29:44,291 INFO: Microblog startup [in /home/senay/Documents/blog/app/__init__.py:46]
2019-10-07 16:29:56,251 INFO: Microblog startup [in /home/senay/Documents/blog/app/__init__.py:46]
2019-10-07 16:31:18,321 ERROR: Exception on /user/senay [GET] [in /home/senay/Documents/blog/venv/lib/python3.5/site-packages/flask/app.py:1891]
Traceback (most recent call last):
  File "/home/senay/Documents/blog/venv/lib/python3.5/site-packages/sqlalchemy/engine/base.py", line 1249, in _execute_context
    cursor, statement, parameters, context
  File "/home/senay/Documents/blog/venv/lib/python3.5/site-packages/sqlalchemy/engine/default.py", line 552, in do_execute
    cursor.execute(statement, parameters)
sqlite3.OperationalError: no such table: followers

The above exception was the direct cause of the following exception:

Traceback (most recent call last):
  File "/home/senay/Documents/blog/venv/lib/python3.5/site-packages/flask/app.py", line 2446, in wsgi_app
    response = self.full_dispatch_request()
  File "/home/senay/Documents/blog/venv/lib/python3.5/site-packages/flask/app.py", line 1951, in full_dispatch_request
    rv = self.handle_user_exception(e)
  File "/home/senay/Documents/blog/venv/lib/python3.5/site-packages/flask/app.py", line 1820, in handle_user_exception
    reraise(exc_type, exc_value, tb)
  File "/home/senay/Documents/blog/venv/lib/python3.5/site-packages/flask/_compat.py", line 39, in reraise
    raise value
  File "/home/senay/Documents/blog/venv/lib/python3.5/site-packages/flask/app.py", line 1949, in full_dispatch_request
    rv = self.dispatch_request()
  File "/home/senay/Documents/blog/venv/lib/python3.5/site-packages/flask/app.py", line 1935, in dispatch_request
    return self.view_functions[rule.endpoint](**req.view_args)
  File "/home/senay/Documents/blog/venv/lib/python3.5/site-packages/flask_login/utils.py", line 261, in decorated_view
    return func(*args, **kwargs)
  File "/home/senay/Documents/blog/app/routes.py", line 81, in user
    return render_template('user.html', user=user, posts=posts)
  File "/home/senay/Documents/blog/venv/lib/python3.5/site-packages/flask/templating.py", line 140, in render_template
    ctx.app,
  File "/home/senay/Documents/blog/venv/lib/python3.5/site-packages/flask/templating.py", line 120, in _render
    rv = template.render(context)
  File "/home/senay/Documents/blog/venv/lib/python3.5/site-packages/jinja2/environment.py", line 1008, in render
    return self.environment.handle_exception(exc_info, True)
  File "/home/senay/Documents/blog/venv/lib/python3.5/site-packages/jinja2/environment.py", line 780, in handle_exception
    reraise(exc_type, exc_value, tb)
  File "/home/senay/Documents/blog/venv/lib/python3.5/site-packages/jinja2/_compat.py", line 37, in reraise
    raise value.with_traceback(tb)
  File "/home/senay/Documents/blog/app/templates/user.html", line 2, in top-level template code
    {% extends "base.html" %}
  File "/home/senay/Documents/blog/app/templates/base.html", line 30, in top-level template code
    {% block content %}{% endblock %}
  File "/home/senay/Documents/blog/app/templates/user.html", line 15, in block "content"
    <p>{{ user.followers.count() }} followers, {{ user.followed.count() }} following.</p>
  File "/home/senay/Documents/blog/venv/lib/python3.5/site-packages/sqlalchemy/orm/dynamic.py", line 335, in count
    return self._clone(sess).count()
  File "/home/senay/Documents/blog/venv/lib/python3.5/site-packages/sqlalchemy/orm/query.py", line 3578, in count
    return self.from_self(col).scalar()
  File "/home/senay/Documents/blog/venv/lib/python3.5/site-packages/sqlalchemy/orm/query.py", line 3322, in scalar
    ret = self.one()
  File "/home/senay/Documents/blog/venv/lib/python3.5/site-packages/sqlalchemy/orm/query.py", line 3292, in one
    ret = self.one_or_none()
  File "/home/senay/Documents/blog/venv/lib/python3.5/site-packages/sqlalchemy/orm/query.py", line 3261, in one_or_none
    ret = list(self)
  File "/home/senay/Documents/blog/venv/lib/python3.5/site-packages/sqlalchemy/orm/query.py", line 3334, in __iter__
    return self._execute_and_instances(context)
  File "/home/senay/Documents/blog/venv/lib/python3.5/site-packages/sqlalchemy/orm/query.py", line 3359, in _execute_and_instances
    result = conn.execute(querycontext.statement, self._params)
  File "/home/senay/Documents/blog/venv/lib/python3.5/site-packages/sqlalchemy/engine/base.py", line 988, in execute
    return meth(self, multiparams, params)
  File "/home/senay/Documents/blog/venv/lib/python3.5/site-packages/sqlalchemy/sql/elements.py", line 287, in _execute_on_connection
    return connection._execute_clauseelement(self, multiparams, params)
  File "/home/senay/Documents/blog/venv/lib/python3.5/site-packages/sqlalchemy/engine/base.py", line 1107, in _execute_clauseelement
    distilled_params,
  File "/home/senay/Documents/blog/venv/lib/python3.5/site-packages/sqlalchemy/engine/base.py", line 1253, in _execute_context
    e, statement, parameters, cursor, context
  File "/home/senay/Documents/blog/venv/lib/python3.5/site-packages/sqlalchemy/engine/base.py", line 1473, in _handle_dbapi_exception
    util.raise_from_cause(sqlalchemy_exception, exc_info)
  File "/home/senay/Documents/blog/venv/lib/python3.5/site-packages/sqlalchemy/util/compat.py", line 398, in raise_from_cause
    reraise(type(exception), exception, tb=exc_tb, cause=cause)
  File "/home/senay/Documents/blog/venv/lib/python3.5/site-packages/sqlalchemy/util/compat.py", line 152, in reraise
    raise value.with_traceback(tb)
  File "/home/senay/Documents/blog/venv/lib/python3.5/site-packages/sqlalchemy/engine/base.py", line 1249, in _execute_context
    cursor, statement, parameters, context
  File "/home/senay/Documents/blog/venv/lib/python3.5/site-packages/sqlalchemy/engine/default.py", line 552, in do_execute
    cursor.execute(statement, parameters)
sqlalchemy.exc.OperationalError: (sqlite3.OperationalError) no such table: followers
[SQL: SELECT count(*) AS count_1 
FROM (SELECT user.id AS user_id, user.username AS user_username, user.email AS user_email, user.password_hash AS user_password_hash, user.about_me AS user_about_me, user.last_seen AS user_last_seen 
FROM user, followers 
WHERE followers.followed_id = ? AND followers.follower_id = user.id) AS anon_1]
[parameters: (2,)]
(Background on this error at: http://sqlalche.me/e/e3q8)
2019-10-07 16:34:38,447 INFO: Microblog startup [in /home/senay/Documents/blog/app/__init__.py:46]
2019-10-07 16:34:49,408 INFO: Microblog startup [in /home/senay/Documents/blog/app/__init__.py:46]
