2019-09-14 14:04:43,872 INFO: Microblog startup [in /home/senay/Documents/blog/app/__init__.py:46]
2019-09-14 14:05:05,542 ERROR: Exception on /edit_profile [POST] [in /home/senay/Documents/blog/venv/lib/python3.5/site-packages/flask/app.py:1891]
Traceback (most recent call last):
  File "/home/senay/Documents/blog/venv/lib/python3.5/site-packages/flask/app.py", line 2446, in wsgi_app
    response = self.full_dispatch_request()
  File "/home/senay/Documents/blog/venv/lib/python3.5/site-packages/flask/app.py", line 1951, in full_dispatch_request
    rv = self.handle_user_exception(e)
  File "/home/senay/Documents/blog/venv/lib/python3.5/site-packages/flask/app.py", line 1820, in handle_user_exception
    reraise(exc_type, exc_value, tb)
  File "/home/senay/Documents/blog/venv/lib/python3.5/site-packages/flask/_compat.py", line 39, in reraise
    raise value
  File "/home/senay/Documents/blog/venv/lib/python3.5/site-packages/flask/app.py", line 1949, in full_dispatch_request
    rv = self.dispatch_request()
  File "/home/senay/Documents/blog/venv/lib/python3.5/site-packages/flask/app.py", line 1935, in dispatch_request
    return self.view_functions[rule.endpoint](**req.view_args)
  File "/home/senay/Documents/blog/venv/lib/python3.5/site-packages/flask_login/utils.py", line 261, in decorated_view
    return func(*args, **kwargs)
  File "/home/senay/Documents/blog/app/routes.py", line 86, in edit_profile
    if form.validate_on_submit():
  File "/home/senay/Documents/blog/venv/lib/python3.5/site-packages/flask_wtf/form.py", line 101, in validate_on_submit
    return self.is_submitted() and self.validate()
  File "/home/senay/Documents/blog/venv/lib/python3.5/site-packages/wtforms/form.py", line 310, in validate
    return super(Form, self).validate(extra)
  File "/home/senay/Documents/blog/venv/lib/python3.5/site-packages/wtforms/form.py", line 152, in validate
    if not field.validate(self, extra):
  File "/home/senay/Documents/blog/venv/lib/python3.5/site-packages/wtforms/fields/core.py", line 206, in validate
    stop_validation = self._run_validation_chain(form, chain)
  File "/home/senay/Documents/blog/venv/lib/python3.5/site-packages/wtforms/fields/core.py", line 226, in _run_validation_chain
    validator(form, self)
  File "/home/senay/Documents/blog/app/forms.py", line 43, in validate_username
    raise ValidationError('Please use a different username.')
NameError: name 'ValidationError' is not defined
2019-09-14 14:09:03,282 INFO: Microblog startup [in /home/senay/Documents/blog/app/__init__.py:46]
2019-09-14 14:09:56,118 ERROR: Exception on /edit_profile [POST] [in /home/senay/Documents/blog/venv/lib/python3.5/site-packages/flask/app.py:1891]
Traceback (most recent call last):
  File "/home/senay/Documents/blog/venv/lib/python3.5/site-packages/flask/app.py", line 2446, in wsgi_app
    response = self.full_dispatch_request()
  File "/home/senay/Documents/blog/venv/lib/python3.5/site-packages/flask/app.py", line 1951, in full_dispatch_request
    rv = self.handle_user_exception(e)
  File "/home/senay/Documents/blog/venv/lib/python3.5/site-packages/flask/app.py", line 1820, in handle_user_exception
    reraise(exc_type, exc_value, tb)
  File "/home/senay/Documents/blog/venv/lib/python3.5/site-packages/flask/_compat.py", line 39, in reraise
    raise value
  File "/home/senay/Documents/blog/venv/lib/python3.5/site-packages/flask/app.py", line 1949, in full_dispatch_request
    rv = self.dispatch_request()
  File "/home/senay/Documents/blog/venv/lib/python3.5/site-packages/flask/app.py", line 1935, in dispatch_request
    return self.view_functions[rule.endpoint](**req.view_args)
  File "/home/senay/Documents/blog/venv/lib/python3.5/site-packages/flask_login/utils.py", line 261, in decorated_view
    return func(*args, **kwargs)
  File "/home/senay/Documents/blog/app/routes.py", line 86, in edit_profile
    if form.validate_on_submit():
  File "/home/senay/Documents/blog/venv/lib/python3.5/site-packages/flask_wtf/form.py", line 101, in validate_on_submit
    return self.is_submitted() and self.validate()
  File "/home/senay/Documents/blog/venv/lib/python3.5/site-packages/wtforms/form.py", line 310, in validate
    return super(Form, self).validate(extra)
  File "/home/senay/Documents/blog/venv/lib/python3.5/site-packages/wtforms/form.py", line 152, in validate
    if not field.validate(self, extra):
  File "/home/senay/Documents/blog/venv/lib/python3.5/site-packages/wtforms/fields/core.py", line 206, in validate
    stop_validation = self._run_validation_chain(form, chain)
  File "/home/senay/Documents/blog/venv/lib/python3.5/site-packages/wtforms/fields/core.py", line 226, in _run_validation_chain
    validator(form, self)
  File "/home/senay/Documents/blog/app/forms.py", line 43, in validate_username
    raise ValidationError('Please use a different username.')
NameError: name 'ValidationError' is not defined
2019-10-03 17:25:49,325 INFO: Microblog startup [in /home/senay/Documents/blog/app/__init__.py:46]
